Workbook

Sheet FY Target Sheet
A1: Status | B1: Type | C1: Projects | D1: Apr-26 Units Target | E1: Apr-26 Units Actual | F1: Apr-26 Rate Target | G1: Apr-26 Rate Actual | H1: Apr-26 Area Target | I1: Apr-26 Area Actual | J1: Apr-26 Sales Value Target | K1: Apr-26 Sales Value Actual | L1: Apr-26 Collection Target | M1: Apr-26 Collection Actual | N1: Apr-26 Construction Target | O1: Apr-26 Construction Actual | P1: May-26 Units Target | Q1: May-26 Units Actual | R1: May-26 Rate Target | S1: May-26 Rate Actual | T1: May-26 Area Target | U1: May-26 Area Actual | V1: May-26 Sales Value Target | W1: May-26 Sales Value Actual | X1: May-26 Collection Target | Y1: May-26 Collection Actual | Z1: May-26 Construction Target | AA1: May-26 Construction Actual | AB1: Jun-26 Units Target | AC1: Jun-26 Units Actual | AD1: Jun-26 Rate Target | AE1: Jun-26 Rate Actual | AF1: Jun-26 Area Target | AG1: Jun-26 Area Actual | AH1: Jun-26 Sales Value Target | AI1: Jun-26 Sales Value Actual | AJ1: Jun-26 Collection Target | AK1: Jun-26 Collection Actual | AL1: Jun-26 Construction Target | AM1: Jun-26 Construction Actual | AN1: Jul-26 Units Target | AO1: Jul-26 Rate Target | AP1: Jul-26 Area Target | AQ1: Jul-26 Sales Value Target | AR1: Jul-26 Collection Target | AS1: Jul-26 Construction Target | AT1: Aug-26 Units Target | AU1: Aug-26 Rate Target | AV1: Aug-26 Area Target | AW1: Aug-26 Sales Value Target | AX1: Aug-26 Collection Target | AY1: Aug-26 Construction Target | AZ1: Sep-26 Units Target | BA1: Sep-26 Rate Target | BB1: Sep-26 Area Target | BC1: Sep-26 Sales Value Target | BD1: Sep-26 Collection Target | BE1: Sep-26 Construction Target | BF1: Oct-26 Units Target | BG1: Oct-26 Rate Target | BH1: Oct-26 Area Target | BI1: Oct-26 Sales Value Target | BJ1: Oct-26 Collection Target | BK1: Oct-26 Construction Target | BL1: Nov-26 Units Target | BM1: Nov-26 Rate Target | BN1: Nov-26 Area Target | BO1: Nov-26 Sales Value Target | BP1: Nov-26 Collection Target | BQ1: Nov-26 Construction Target | BR1: Dec-26 Units Target | BS1: Dec-26 Rate Target | BT1: Dec-26 Area Target | BU1: Dec-26 Sales Value Target | BV1: Dec-26 Collection Target | BW1: Dec-26 Construction Target | BX1: Jan-27 Units Target | BY1: Jan-27 Rate Target | BZ1: Jan-27 Area Target | CA1: Jan-27 Sales Value Target | CB1: Jan-27 Collection Target | CC1: Jan-27 Construction Target | CD1: Feb-27 Units Target | CE1: Feb-27 Rate Target | CF1: Feb-27 Area Target | CG1: Feb-27 Sales Value Target | CH1: Feb-27 Collection Target | CI1: Feb-27 Construction Target | CJ1: Mar-27 Units Target | CK1: Mar-27 Rate Target | CL1: Mar-27 Area Target | CM1: Mar-27 Sales Value Target | CN1: Mar-27 Collection Target | CO1: Mar-27 Construction Target
A2: On Going | B2: RESIDENTIAL | C2: NYATI EMERALD I | D2: 5 | E2: =COUNTIF('Booking Apr'!B:B,'FY Target Sheet'!C2)-COUNTIF('Cancel Apr'!A:A,'FY Target Sheet'!C2) -> -1 | F2: 8249.1106 | G2: =(K2/I2) -> 8641.7037 | H2: 6915 | I2: =SUMIF('Booking Apr'!B:B,'FY Target Sheet'!C2,'Booking Apr'!K:K)-SUMIF('Cancel Apr'!A:A,'FY Target Sheet'!C2,'Cancel Apr'!F:F) -> -648 | J2: 57042600 | K2: =SUMIF('Booking Apr'!B:B,C2,'Booking Apr'!L:L)-SUMIF('Cancel Apr'!A:A,'FY Target Sheet'!C2,'Cancel Apr'!G:G) -> -5599824 | L2: 86722920 | M2: =SUMIF('Coll Apr'!A:A,C2,'Coll Apr'!J:J)*100000 -> 57110000 | N2: ='Construction Budget'!G5*10000000 -> 82975269 | O2: ='Construction Budget'!G6*10000000 -> 28323535 | P2: 3 | Q2: =COUNTIF('Booking May'!B:B,'FY Target Sheet'!C2)-COUNTIF('Cancel May'!A:A,'FY Target Sheet'!C2) -> 1 | R2: 8274.327 | S2: =(W2/U2) -> 8450 | T2: 4569 | U2: =SUMIF('Booking May'!B:B,'FY Target Sheet'!C2,'Booking May'!K:K)-SUMIF('Cancel May'!A:A,'FY Target Sheet'!C2,'Cancel May'!F:F) -> 1173 | V2: 37805400 | W2: =SUMIF('Booking May'!B:B,C2,'Booking May'!L:L)-SUMIF('Cancel May'!A:A,'FY Target Sheet'!C2,'Cancel May'!G:G) -> 9911850 | X2: 87309515 | Y2: =SUMIF('Coll May'!A:A,C2,'Coll May'!J:J)*100000 -> 38667000 | Z2: ='Construction Budget'!H5*10000000 -> 85868030 | AA2: ='Construction Budget'!H6*10000000 -> 40911773 | AB2: 5 | AC2: =COUNTIF('Booking Jun'!B:B,C2)-COUNTIF('Cancel Jun'!A:A,C2) -> 2 | AD2: 8268.4677 | AE2: =(AI2/AG2) -> 9516.3408 | AF2: 7440 | AG2: =SUMIF('Booking Jun'!B:B,'FY Target Sheet'!C2,'Booking Jun'!K:K)-SUMIF('Cancel Jun'!A:A,'FY Target Sheet'!C2,'Cancel Jun'!F:F) -> 5818 | AH2: 61517400 | AI2: =SUMIF('Booking Jun'!B:B,C2,'Booking Jun'!L:L)-SUMIF('Cancel Jun'!A:A,'FY Target Sheet'!C2,'Cancel Jun'!G:G) -> 55366071 | AJ2: 77332449 | AK2: =SUMIF('Coll Jun'!A:A,C2,'Coll Jun'!J:J)*100000 -> 27677000 | AL2: ='Construction Budget'!I5*10000000 -> 93591907 | AM2: ='Construction Budget'!I6*10000000 -> 81823547 | AN2: 5 | AO2: 8400 | AP2: 8490 | AQ2: 71316000 | AR2: 83974119 | AS2: ='Construction Budget'!J5*10000000 -> 1.2127371e+08 | AT2: 5 | AU2: 8400 | AV2: 8490 | AW2: 71316000 | AX2: 91105719 | AY2: ='Construction Budget'!K5*10000000 -> 1.2061047e+08 | AZ2: 7 | BA2: 8389.6752 | BB2: 11361 | BC2: 95315100 | BD2: 1.0300307e+08 | BE2: ='Construction Budget'!L5*10000000 -> 1.2921313e+08 | BF2: 7 | BG2: 8810.4616 | BH2: 12847 | BI2: 113188000 | BJ2: 1.1952348e+08 | BK2: ='Construction Budget'!M5*10000000 -> 1.2210436e+08 | BL2: 7 | BM2: 8810.4616 | BN2: 12847 | BO2: 113188000 | BP2: 1.3008375e+08 | BQ2: ='Construction Budget'!N5*10000000 -> 1.3026793e+08 | BR2: 11 | BS2: 8891.5168 | BT2: 20075 | BU2: 178497200 | BV2: 1.9092317e+08 | BW2: ='Construction Budget'!O5*10000000 -> 1.2130212e+08 | BX2: 0 | BY2: 0 | BZ2: 0 | CA2: 0 | CB2: 2.2555312e+08 | CC2: ='Construction Budget'!P5*10000000 -> 1.0811711e+08 | CD2: 0 | CE2: 0 | CF2: 0 | CG2: 0 | CH2: 2.5078737e+08 | CI2: ='Construction Budget'!Q5*10000000 -> 1.2130212e+08 | CJ2: 0 | CK2: 0 | CL2: 0 | CM2: 0 | CN2: 2.9458382e+08 | CO2: ='Construction Budget'!R5*10000000 -> 1.1339112e+08
A3: On Going | B3: RESIDENTIAL | C3: NYATI EMERALD II | E3: =COUNTIF('Booking Apr'!B:B,'FY Target Sheet'!C3)-COUNTIF('Cancel Apr'!A:A,'FY Target Sheet'!C3) -> 0 | I3: =SUMIF('Booking Apr'!B:B,'FY Target Sheet'!C3,'Booking Apr'!K:K)-SUMIF('Cancel Apr'!A:A,'FY Target Sheet'!C3,'Cancel Apr'!F:F) -> 0 | K3: =SUMIF('Booking Apr'!B:B,C3,'Booking Apr'!L:L)-SUMIF('Cancel Apr'!A:A,'FY Target Sheet'!C3,'Cancel Apr'!G:G) -> 0 | L3: 4185500 | M3: =SUMIF('Coll Apr'!A:A,C3,'Coll Apr'!J:J)*100000 -> 6546000 | N3: ='Construction Budget'!G8*10000000 -> 15625200 | O3: ='Construction Budget'!G9*10000000 -> 2412749.9 | Q3: =COUNTIF('Booking May'!B:B,'FY Target Sheet'!C3)-COUNTIF('Cancel May'!A:A,'FY Target Sheet'!C3) -> 0 | U3: =SUMIF('Booking May'!B:B,'FY Target Sheet'!C3,'Booking May'!K:K)-SUMIF('Cancel May'!A:A,'FY Target Sheet'!C3,'Cancel May'!F:F) -> 0 | W3: =SUMIF('Booking May'!B:B,C3,'Booking May'!L:L)-SUMIF('Cancel May'!A:A,'FY Target Sheet'!C3,'Cancel May'!G:G) -> 0 | X3: 18985373 | Y3: =SUMIF('Coll May'!A:A,C3,'Coll May'!J:J)*100000 -> 19258000 | Z3: ='Construction Budget'!H8*10000000 -> 24271144 | AA3: ='Construction Budget'!H9*10000000 -> 6273149.7 | AC3: =COUNTIF('Booking Jun'!B:B,C3)-COUNTIF('Cancel Jun'!A:A,C3) -> 0 | AG3: =SUMIF('Booking Jun'!B:B,'FY Target Sheet'!C3,'Booking Jun'!K:K)-SUMIF('Cancel Jun'!A:A,'FY Target Sheet'!C3,'Cancel Jun'!F:F) -> 0 | AI3: =SUMIF('Booking Jun'!B:B,C3,'Booking Jun'!L:L)-SUMIF('Cancel Jun'!A:A,'FY Target Sheet'!C3,'Cancel Jun'!G:G) -> 0 | AJ3: 16040411 | AK3: =SUMIF('Coll Jun'!A:A,C3,'Coll Jun'!J:J)*100000 -> 18610000 | AL3: ='Construction Budget'!I8*10000000 -> 22916960 | AM3: ='Construction Budget'!I8*10000000 -> 22916960 | AR3: 16040411 | AS3: ='Construction Budget'!J8*10000000 -> 21875280 | AX3: 16040411 | AY3: ='Construction Budget'!K8*10000000 -> 23021128 | BD3: 16040411 | BE3: ='Construction Budget'!L8*10000000 -> 18750240 | BJ3: 16040411 | BK3: ='Construction Budget'!M8*10000000 -> 21666944 | BP3: 16040411 | BQ3: ='Construction Budget'!N8*10000000 -> 17708560 | BV3: 16040411 | BW3: ='Construction Budget'!O8*10000000 -> 16041872 | CB3: 16040411 | CC3: ='Construction Budget'!P8*10000000 -> 19791920 | CH3: 16040411 | CI3: ='Construction Budget'!Q8*10000000 -> 21979448 | CN3: 16040411 | CO3: ='Construction Budget'!R8*10000000 -> 26354504
A4: On Going | B4: RESIDENTIAL | C4: NYATI EMERALD III | D4: 19 | E4: =COUNTIF('Booking Apr'!B:B,'FY Target Sheet'!C4)-COUNTIF('Cancel Apr'!A:A,'FY Target Sheet'!C4) -> 1 | F4: 8388.7221 | G4: =(K4/I4) -> 8803.5834 | H4: 27372 | I4: =SUMIF('Booking Apr'!B:B,'FY Target Sheet'!C4,'Booking Apr'!K:K)-SUMIF('Cancel Apr'!A:A,'FY Target Sheet'!C4,'Cancel Apr'!F:F) -> 2223 | J4: 229616100 | K4: =SUMIF('Booking Apr'!B:B,C4,'Booking Apr'!L:L)-SUMIF('Cancel Apr'!A:A,'FY Target Sheet'!C4,'Cancel Apr'!G:G) -> 19570366 | L4: 1.074241e+08 | M4: =SUMIF('Coll Apr'!A:A,C4,'Coll Apr'!J:J)*100000 -> 117679000 | N4: ='Construction Budget'!G11*10000000 -> 55858996 | O4: ='Construction Budget'!G12*10000000 -> 24366196 | P4: 17 | Q4: =COUNTIF('Booking May'!B:B,'FY Target Sheet'!C4)-COUNTIF('Cancel May'!A:A,'FY Target Sheet'!C4) -> 4 | R4: 8287.2958 | S4: =(W4/U4) -> 8356.5143 | T4: 24484 | U4: =SUMIF('Booking May'!B:B,'FY Target Sheet'!C4,'Booking May'!K:K)-SUMIF('Cancel May'!A:A,'FY Target Sheet'!C4,'Cancel May'!F:F) -> 5217 | V4: 202906150 | W4: =SUMIF('Booking May'!B:B,C4,'Booking May'!L:L)-SUMIF('Cancel May'!A:A,'FY Target Sheet'!C4,'Cancel May'!G:G) -> 43595935 | X4: 1.0779113e+08 | Y4: =SUMIF('Coll May'!A:A,C4,'Coll May'!J:J)*100000 -> 75792000 | Z4: ='Construction Budget'!H11*10000000 -> 60158222 | AA4: ='Construction Budget'!H12*10000000 -> 19303090 | AB4: 15 | AC4: =COUNTIF('Booking Jun'!B:B,C4)-COUNTIF('Cancel Jun'!A:A,C4) -> 5 | AD4: 8205.8815 | AE4: =(AI4/AG4) -> 8078.1286 | AF4: 21270 | AG4: =SUMIF('Booking Jun'!B:B,'FY Target Sheet'!C4,'Booking Jun'!K:K)-SUMIF('Cancel Jun'!A:A,'FY Target Sheet'!C4,'Cancel Jun'!F:F) -> 6390 | AH4: 174539100 | AI4: =SUMIF('Booking Jun'!B:B,C4,'Booking Jun'!L:L)-SUMIF('Cancel Jun'!A:A,'FY Target Sheet'!C4,'Cancel Jun'!G:G) -> 51619242 | AJ4: 101465380 | AK4: =SUMIF('Coll Jun'!A:A,C4,'Coll Jun'!J:J)*100000 -> 71062000 | AL4: ='Construction Budget'!I11*10000000 -> 81148015 | AM4: ='Construction Budget'!I12*10000000 -> 50631056 | AN4: 13 | AO4: 8312.8091 | AP4: 18924 | AQ4: 157311600 | AR4: 118057915 | AS4: ='Construction Budget'!J11*10000000 -> 66208722 | AT4: 13 | AU4: 8305.3726 | AV4: 18399 | AW4: 152810550 | AX4: 1.2208322e+08 | AY4: ='Construction Budget'!K11*10000000 -> 88355540 | AZ4: 10 | BA4: 8309.1432 | BB4: 14355 | BC4: 119277750 | BD4: 125542325 | BE4: ='Construction Budget'!L11*10000000 -> 88960644 | BF4: 13 | BG4: 8405.3726 | BH4: 18399 | BI4: 154650450 | BJ4: 130511780 | BK4: ='Construction Budget'!M11*10000000 -> 94609008 | BL4: 15 | BM4: 8399.1106 | BN4: 20745 | BO4: 174239550 | BP4: 1.546888e+08 | BQ4: ='Construction Budget'!N11*10000000 -> 91003889 | BR4: 12 | BS4: 8400.8353 | BT4: 16701 | BU4: 140302350 | BV4: 1.6129693e+08 | BW4: ='Construction Budget'!O11*10000000 -> 70125891 | BX4: 21 | BY4: 8515.8714 | BZ4: 30933 | CA4: 263421450 | CB4: 1.9053193e+08 | CC4: ='Construction Budget'!P11*10000000 -> 52994112 | CD4: 20 | CE4: 8504.2203 | CF4: 28185 | CG4: 239691450 | CH4: 2.0853668e+08 | CI4: ='Construction Budget'!Q11*10000000 -> 96758078 | CJ4: 23 | CK4: 8519.2476 | CL4: 34329 | CM4: 292457250 | CN4: 2.5954999e+08 | CO4: ='Construction Budget'!R11*10000000 -> 53830405
A5: Near Completion | B5: RESIDENTIAL | C5: NYATI EQUINOX I | D5: 10 | E5: =COUNTIF('Booking Apr'!B:B,'FY Target Sheet'!C5)-COUNTIF('Cancel Apr'!A:A,'FY Target Sheet'!C5) -> 7 | F5: 8057.5034 | G5: =(K5/I5) -> 8428.2704 | H5: 14067 | I5: =SUMIF('Booking Apr'!B:B,'FY Target Sheet'!C5,'Booking Apr'!K:K)-SUMIF('Cancel Apr'!A:A,'FY Target Sheet'!C5,'Cancel Apr'!F:F) -> 11992 | J5: 113344900 | K5: =SUMIF('Booking Apr'!B:B,C5,'Booking Apr'!L:L)-SUMIF('Cancel Apr'!A:A,'FY Target Sheet'!C5,'Cancel Apr'!G:G) -> 101071819 | L5: 1.5768781e+08 | M5: =SUMIF('Coll Apr'!A:A,C5,'Coll Apr'!J:J)*100000 -> 106054000 | N5: ='Construction Budget'!G14*10000000 -> 56000717 | O5: ='Construction Budget'!G15*10000000 -> 37146927 | P5: 13 | Q5: =COUNTIF('Booking May'!B:B,'FY Target Sheet'!C5)-COUNTIF('Cancel May'!A:A,'FY Target Sheet'!C5) -> 6 | R5: 8091.6436 | S5: =(W5/U5) -> 8544.5626 | T5: 19877 | U5: =SUMIF('Booking May'!B:B,'FY Target Sheet'!C5,'Booking May'!K:K)-SUMIF('Cancel May'!A:A,'FY Target Sheet'!C5,'Cancel May'!F:F) -> 6363 | V5: 160837600 | W5: =SUMIF('Booking May'!B:B,C5,'Booking May'!L:L)-SUMIF('Cancel May'!A:A,'FY Target Sheet'!C5,'Cancel May'!G:G) -> 54369052 | X5: 1.76304e+08 | Y5: =SUMIF('Coll May'!A:A,C5,'Coll May'!J:J)*100000 -> 1.29128e+08 | Z5: ='Construction Budget'!H14*10000000 -> 66500851 | AA5: ='Construction Budget'!H15*10000000 -> 72783816 | AB5: 14 | AC5: =COUNTIF('Booking Jun'!B:B,C5)-COUNTIF('Cancel Jun'!A:A,C5) -> 12 | AD5: 8070.7491 | AE5: =(AI5/AG5) -> 8288.3515 | AF5: 20437 | AG5: =SUMIF('Booking Jun'!B:B,'FY Target Sheet'!C5,'Booking Jun'!K:K)-SUMIF('Cancel Jun'!A:A,'FY Target Sheet'!C5,'Cancel Jun'!F:F) -> 14307 | AH5: 164941900 | AI5: =SUMIF('Booking Jun'!B:B,C5,'Booking Jun'!L:L)-SUMIF('Cancel Jun'!A:A,'FY Target Sheet'!C5,'Cancel Jun'!G:G) -> 118581445 | AJ5: 1.4831923e+08 | AK5: =SUMIF('Coll Jun'!A:A,C5,'Coll Jun'!J:J)*100000 -> 1.06736e+08 | AL5: ='Construction Budget'!I14*10000000 -> 80501030 | AM5: ='Construction Budget'!I15*10000000 -> 95132373 | AN5: 22 | AO5: 8991.4062 | AP5: 29754 | AQ5: 267530300 | AR5: 1.7286602e+08 | AS5: ='Construction Budget'!J14*10000000 -> 84001075 | AT5: 20 | AU5: 8846.3967 | AV5: 25629 | AW5: 226724300 | AX5: 1.9511989e+08 | AY5: ='Construction Budget'!K14*10000000 -> 91001165 | AZ5: 12 | BA5: 8617.7435 | BB5: 15183 | BC5: 130843200 | BD5: 2.1756887e+08 | BE5: ='Construction Budget'!L14*10000000 -> 77000986 | BF5: 10 | BG5: 8269.1194 | BH5: 14922 | BI5: 123391800 | BJ5: 2.1756806e+08 | BK5: ='Construction Budget'!M14*10000000 -> 87501120 | BL5: 15 | BM5: 8297.5304 | BN5: 23567 | BO5: 195547900 | BP5: 2.5452585e+08 | BQ5: ='Construction Budget'!N14*10000000 -> 84001075 | BR5: 16 | BS5: 8253.7164 | BT5: 22401 | BU5: 184891500 | BV5: 3.2237156e+08 | BW5: ='Construction Budget'!O14*10000000 -> 73500941 | BX5: 16 | BY5: 8353.7164 | BZ5: 22401 | CA5: 187131600 | CB5: 351678704 | CC5: ='Construction Budget'!P14*10000000 -> 0 | CD5: 17 | CE5: 8314.8795 | CF5: 10827 | CG5: 90025200 | CH5: 3.6298267e+08 | CI5: ='Construction Budget'!Q14*10000000 -> 0 | CJ5: 16 | CK5: 8365.7361 | CL5: 23535 | CM5: 196887600 | CN5: 239880364 | CO5: ='Construction Budget'!R14*10000000 -> 0
A6: On Going | B6: RESIDENTIAL | C6: NYATI EQUINOX II | D6: 5 | E6: =COUNTIF('Booking Apr'!B:B,'FY Target Sheet'!C6)-COUNTIF('Cancel Apr'!A:A,'FY Target Sheet'!C6) -> 2 | F6: 6629.1161 | G6: =(K6/I6) -> 6754.142 | H6: 6268 | I6: =SUMIF('Booking Apr'!B:B,'FY Target Sheet'!C6,'Booking Apr'!K:K)-SUMIF('Cancel Apr'!A:A,'FY Target Sheet'!C6,'Cancel Apr'!F:F) -> 1641 | J6: 41551300 | K6: =SUMIF('Booking Apr'!B:B,C6,'Booking Apr'!L:L)-SUMIF('Cancel Apr'!A:A,'FY Target Sheet'!C6,'Cancel Apr'!G:G) -> 11083547 | L6: 18423402 | M6: =SUMIF('Coll Apr'!A:A,C6,'Coll Apr'!J:J)*100000 -> 18198000 | N6: ='Construction Budget'!G17*10000000 -> 19343368 | O6: ='Construction Budget'!G18*10000000 -> 6718658.4 | P6: 6 | Q6: =COUNTIF('Booking May'!B:B,'FY Target Sheet'!C6)-COUNTIF('Cancel May'!A:A,'FY Target Sheet'!C6) -> 1 | R6: 6624.3366 | S6: =(W6/U6) -> 6907 | T6: 7499 | U6: =SUMIF('Booking May'!B:B,'FY Target Sheet'!C6,'Booking May'!K:K)-SUMIF('Cancel May'!A:A,'FY Target Sheet'!C6,'Cancel May'!F:F) -> 733 | V6: 49675900 | W6: =SUMIF('Booking May'!B:B,C6,'Booking May'!L:L)-SUMIF('Cancel May'!A:A,'FY Target Sheet'!C6,'Cancel May'!G:G) -> 5062831 | X6: 22984762 | Y6: =SUMIF('Coll May'!A:A,C6,'Coll May'!J:J)*100000 -> 9039000 | Z6: ='Construction Budget'!H17*10000000 -> 14646424 | AA6: ='Construction Budget'!H18*10000000 -> 11757652 | AB6: 7 | AC6: =COUNTIF('Booking Jun'!B:B,C6)-COUNTIF('Cancel Jun'!A:A,C6) -> 2 | AD6: 6644.3553 | AE6: =(AI6/AG6) -> 6559.6726 | AF6: 8229 | AG6: =SUMIF('Booking Jun'!B:B,'FY Target Sheet'!C6,'Booking Jun'!K:K)-SUMIF('Cancel Jun'!A:A,'FY Target Sheet'!C6,'Cancel Jun'!F:F) -> 1466 | AH6: 54676400 | AI6: =SUMIF('Booking Jun'!B:B,C6,'Booking Jun'!L:L)-SUMIF('Cancel Jun'!A:A,'FY Target Sheet'!C6,'Cancel Jun'!G:G) -> 9616480 | AJ6: 22339378 | AK6: =SUMIF('Coll Jun'!A:A,C6,'Coll Jun'!J:J)*100000 -> 13207000 | AL6: ='Construction Budget'!I17*10000000 -> 9540521.4 | AM6: ='Construction Budget'!I18*10000000 -> 16796846 | AN6: 9 | AO6: 6708.1879 | AP6: 10998 | AQ6: 73776650 | AR6: 28762030 | AS6: ='Construction Budget'!J17*10000000 -> 34801443 | AT6: 9 | AU6: 6708.1879 | AV6: 10998 | AW6: 73776650 | AX6: 36945329 | AY6: ='Construction Budget'!K17*10000000 -> 35715187 | AZ6: 7 | BA6: 6695.1948 | BB6: 9037 | BC6: 60504475 | BD6: 45503801 | BE6: ='Construction Budget'!L17*10000000 -> 36746355 | BF6: 8 | BG6: 6787.3707 | BH6: 9767 | BI6: 66292250 | BJ6: 53024445 | BK6: ='Construction Budget'!M17*10000000 -> 39796670 | BL6: 11 | BM6: 6776.5127 | BN6: 13767 | BO6: 93292250 | BP6: 65975589 | BQ6: ='Construction Budget'!N17*10000000 -> 36560997 | BR6: 12 | BS6: 7235.7868 | BT6: 14571 | BU6: 105432650 | BV6: 82486549 | BW6: ='Construction Budget'!O17*10000000 -> 39768326 | BX6: 13 | BY6: 7269.1273 | BZ6: 15802 | CA6: 114866750 | CB6: 1.0765911e+08 | CC6: ='Construction Budget'!P17*10000000 -> 46787648 | CD6: 14 | CE6: 7229.7347 | CF6: 17340 | CG6: 125363600 | CH6: 1.2553169e+08 | CI6: ='Construction Budget'!Q17*10000000 -> 57529433 | CJ6: 14 | CK6: 7229.7347 | CL6: 17340 | CM6: 125363600 | CN6: 1.1053288e+08 | CO6: ='Construction Budget'!R17*10000000 -> 28768749
A7: Completed | B7: RESIDENTIAL | C7: NYATI ERA II | D7: 3 | E7: =COUNTIF('Booking Apr'!B:B,'FY Target Sheet'!C7)-COUNTIF('Cancel Apr'!A:A,'FY Target Sheet'!C7) -> -1 | F7: 9318.7588 | G7: =(K7/I7) -> 3145.6446 | H7: 1418 | I7: =SUMIF('Booking Apr'!B:B,'FY Target Sheet'!C7,'Booking Apr'!K:K)-SUMIF('Cancel Apr'!A:A,'FY Target Sheet'!C7,'Cancel Apr'!F:F) -> -574 | J7: 13214000 | K7: =SUMIF('Booking Apr'!B:B,C7,'Booking Apr'!L:L)-SUMIF('Cancel Apr'!A:A,'FY Target Sheet'!C7,'Cancel Apr'!G:G) -> -1805600 | L7: 36161600 | M7: =SUMIF('Coll Apr'!A:A,C7,'Coll Apr'!J:J)*100000 -> 48702000 | P7: 3 | Q7: =COUNTIF('Booking May'!B:B,'FY Target Sheet'!C7)-COUNTIF('Cancel May'!A:A,'FY Target Sheet'!C7) -> 1 | R7: 9318.7588 | S7: =(W7/U7) -> 11682.242 | T7: 1418 | U7: =SUMIF('Booking May'!B:B,'FY Target Sheet'!C7,'Booking May'!K:K)-SUMIF('Cancel May'!A:A,'FY Target Sheet'!C7,'Cancel May'!F:F) -> 248 | V7: 13214000 | W7: =SUMIF('Booking May'!B:B,C7,'Booking May'!L:L)-SUMIF('Cancel May'!A:A,'FY Target Sheet'!C7,'Cancel May'!G:G) -> 2897196 | X7: 37247500 | Y7: =SUMIF('Coll May'!A:A,C7,'Coll May'!J:J)*100000 -> 56647000 | AB7: 3 | AC7: =COUNTIF('Booking Jun'!B:B,C7)-COUNTIF('Cancel Jun'!A:A,C7) -> 2 | AD7: 9318.7588 | AE7: =(AI7/AG7) -> 8814.739 | AF7: 1418 | AG7: =SUMIF('Booking Jun'!B:B,'FY Target Sheet'!C7,'Booking Jun'!K:K)-SUMIF('Cancel Jun'!A:A,'FY Target Sheet'!C7,'Cancel Jun'!F:F) -> 977 | AH7: 13214000 | AI7: =SUMIF('Booking Jun'!B:B,C7,'Booking Jun'!L:L)-SUMIF('Cancel Jun'!A:A,'FY Target Sheet'!C7,'Cancel Jun'!G:G) -> 8612000 | AJ7: 40551000 | AK7: =SUMIF('Coll Jun'!A:A,C7,'Coll Jun'!J:J)*100000 -> 37301000 | AN7: 3 | AO7: 9318.7588 | AP7: 1418 | AQ7: 13214000 | AR7: 36859167 | AT7: 5 | AU7: 9384.1904 | AV7: 2353 | AW7: 22081000 | AX7: 38189217 | AZ7: 5 | BA7: 9384.1904 | BB7: 2353 | BC7: 22081000 | BD7: 41292667 | BF7: 4 | BG7: 9237.7696 | BH7: 1901 | BI7: 17561000 | BJ7: 19186250 | BL7: 4 | BM7: 9237.7696 | BN7: 1901 | BO7: 17561000 | BP7: 19821000 | BR7: 4 | BS7: 9237.7696 | BT7: 1901 | BU7: 17561000 | BV7: 18691000 | BX7: 2 | BY7: 9000 | BZ7: 966 | CA7: 8694000 | CB7: 16230950 | CD7: 2 | CE7: 9000 | CF7: 966 | CG7: 8694000 | CH7: 14866300 | CJ7: 2 | CK7: 9000 | CL7: 966 | CM7: 8694000 | CN7: 10910750
A8: Near Completion | B8: RESIDENTIAL | C8: NYATI ERA III | E8: =COUNTIF('Booking Apr'!B:B,'FY Target Sheet'!C8)-COUNTIF('Cancel Apr'!A:A,'FY Target Sheet'!C8) -> 0 | I8: =SUMIF('Booking Apr'!B:B,'FY Target Sheet'!C8,'Booking Apr'!K:K)-SUMIF('Cancel Apr'!A:A,'FY Target Sheet'!C8,'Cancel Apr'!F:F) -> 0 | K8: =SUMIF('Booking Apr'!B:B,C8,'Booking Apr'!L:L)-SUMIF('Cancel Apr'!A:A,'FY Target Sheet'!C8,'Cancel Apr'!G:G) -> 0 | L8: 46511600 | M8: =SUMIF('Coll Apr'!A:A,C8,'Coll Apr'!J:J)*100000 -> 43478000 | N8: ='Construction Budget'!G20*10000000 -> 22000282 | O8: ='Construction Budget'!G21*10000000 -> 30152850 | Q8: =COUNTIF('Booking May'!B:B,'FY Target Sheet'!C8)-COUNTIF('Cancel May'!A:A,'FY Target Sheet'!C8) -> 0 | U8: =SUMIF('Booking May'!B:B,'FY Target Sheet'!C8,'Booking May'!K:K)-SUMIF('Cancel May'!A:A,'FY Target Sheet'!C8,'Cancel May'!F:F) -> 0 | W8: =SUMIF('Booking May'!B:B,C8,'Booking May'!L:L)-SUMIF('Cancel May'!A:A,'FY Target Sheet'!C8,'Cancel May'!G:G) -> 0 | X8: 35272800 | Y8: =SUMIF('Coll May'!A:A,C8,'Coll May'!J:J)*100000 -> 61047000 | Z8: ='Construction Budget'!H20*10000000 -> 30000384 | AA8: ='Construction Budget'!H21*10000000 -> 25144412 | AC8: =COUNTIF('Booking Jun'!B:B,C8)-COUNTIF('Cancel Jun'!A:A,C8) -> 0 | AE8: =(AI8/AG8) -> #DIV/0! | AG8: =SUMIF('Booking Jun'!B:B,'FY Target Sheet'!C8,'Booking Jun'!K:K)-SUMIF('Cancel Jun'!A:A,'FY Target Sheet'!C8,'Cancel Jun'!F:F) -> 0 | AI8: =SUMIF('Booking Jun'!B:B,C8,'Booking Jun'!L:L)-SUMIF('Cancel Jun'!A:A,'FY Target Sheet'!C8,'Cancel Jun'!G:G) -> 0 | AJ8: 21446000 | AK8: =SUMIF('Coll Jun'!A:A,C8,'Coll Jun'!J:J)*100000 -> 40389000 | AL8: ='Construction Budget'!I20*10000000 -> 36000461 | AM8: ='Construction Budget'!I21*10000000 -> 43951614 | AR8: 23590600 | AS8: ='Construction Budget'!J20*10000000 -> 34000435 | AX8: 25735200 | AY8: ='Construction Budget'!K20*10000000 -> 46000589 | BD8: 64338000 | BE8: ='Construction Budget'!L20*10000000 -> 32000410 | BJ8: 1.351098e+08 | BK8: ='Construction Budget'!M20*10000000 -> 0 | BP8: 0 | BQ8: ='Construction Budget'!N20*10000000 -> 0 | BV8: 0 | BW8: ='Construction Budget'!O20*10000000 -> 0 | CB8: 0 | CC8: ='Construction Budget'!P20*10000000 -> 0 | CH8: 0 | CI8: ='Construction Budget'!Q20*10000000 -> 0 | CN8: 0 | CO8: ='Construction Budget'!R20*10000000 -> 0
A9: On Going | B9: RESIDENTIAL | C9: NYATI ERA IV | D9: 4 | E9: =COUNTIF('Booking Apr'!B:B,'FY Target Sheet'!C9)-COUNTIF('Cancel Apr'!A:A,'FY Target Sheet'!C9) -> 3 | F9: 6930.7028 | G9: =(K9/I9) -> 6766.755 | H9: 5037 | I9: =SUMIF('Booking Apr'!B:B,'FY Target Sheet'!C9,'Booking Apr'!K:K)-SUMIF('Cancel Apr'!A:A,'FY Target Sheet'!C9,'Cancel Apr'!F:F) -> 3845 | J9: 34909950 | K9: =SUMIF('Booking Apr'!B:B,C9,'Booking Apr'!L:L)-SUMIF('Cancel Apr'!A:A,'FY Target Sheet'!C9,'Cancel Apr'!G:G) -> 26018173 | L9: 16961620 | M9: =SUMIF('Coll Apr'!A:A,C9,'Coll Apr'!J:J)*100000 -> 14163000 | N9: ='Construction Budget'!G23*10000000 -> 21507854 | O9: ='Construction Budget'!G24*10000000 -> 9451000 | P9: 5 | Q9: =COUNTIF('Booking May'!B:B,'FY Target Sheet'!C9)-COUNTIF('Cancel May'!A:A,'FY Target Sheet'!C9) -> 8 | R9: 6972.0171 | S9: =(W9/U9) -> 6844.9636 | T9: 6663 | U9: =SUMIF('Booking May'!B:B,'FY Target Sheet'!C9,'Booking May'!K:K)-SUMIF('Cancel May'!A:A,'FY Target Sheet'!C9,'Cancel May'!F:F) -> 10064 | V9: 46454550 | W9: =SUMIF('Booking May'!B:B,C9,'Booking May'!L:L)-SUMIF('Cancel May'!A:A,'FY Target Sheet'!C9,'Cancel May'!G:G) -> 68887714 | X9: 28976593 | Y9: =SUMIF('Coll May'!A:A,C9,'Coll May'!J:J)*100000 -> 8577000 | Z9: ='Construction Budget'!H23*10000000 -> 32261781 | AA9: ='Construction Budget'!H24*10000000 -> 3800000 | AB9: 6 | AC9: =COUNTIF('Booking Jun'!B:B,C9)-COUNTIF('Cancel Jun'!A:A,C9) -> 6 | AD9: 6997.1227 | AE9: =(AI9/AG9) -> 6831.1112 | AF9: 8289 | AG9: =SUMIF('Booking Jun'!B:B,'FY Target Sheet'!C9,'Booking Jun'!K:K)-SUMIF('Cancel Jun'!A:A,'FY Target Sheet'!C9,'Cancel Jun'!F:F) -> 7529 | AH9: 57999150 | AI9: =SUMIF('Booking Jun'!B:B,C9,'Booking Jun'!L:L)-SUMIF('Cancel Jun'!A:A,'FY Target Sheet'!C9,'Cancel Jun'!G:G) -> 51431436 | AJ9: 30319145 | AK9: =SUMIF('Coll Jun'!A:A,C9,'Coll Jun'!J:J)*100000 -> 15983000 | AL9: ='Construction Budget'!I23*10000000 -> 33460076 | AM9: ='Construction Budget'!I24*10000000 -> 13798044 | AN9: 6 | AO9: 6975.0769 | AP9: 7800 | AQ9: 54405600 | AR9: 35066633 | AS9: ='Construction Budget'!J23*10000000 -> 47132926 | AT9: 6 | AU9: 7070.0034 | AV9: 8527.86 | AW9: 60291999 | AX9: 38100332 | AY9: ='Construction Budget'!K23*10000000 -> 52141184 | AZ9: 8 | BA9: 7020.0307 | BB9: 10497.86 | BC9: 73695299 | BD9: 43586717 | BE9: ='Construction Budget'!L23*10000000 -> 55428813 | BF9: 13 | BG9: 7039.2532 | BH9: 16252.58 | BI9: 114406026 | BJ9: 57539867 | BK9: ='Construction Budget'!M23*10000000 -> 55613166 | BL9: 9 | BM9: 7106.6328 | BN9: 12177.72 | BO9: 86542584 | BP9: 65761915 | BQ9: ='Construction Budget'!N23*10000000 -> 55797519 | BR9: 8 | BS9: 7094.2129 | BT9: 10748 | BU9: 76248600 | BV9: 71330049 | BW9: ='Construction Budget'!O23*10000000 -> 43200061 | BX9: 7 | BY9: 7159.4238 | BZ9: 9414.72 | CA9: 67403970 | CB9: 75970714 | CC9: ='Construction Budget'!P23*10000000 -> 25625072 | CD9: 6 | CE9: 7099.4012 | CF9: 7549.86 | CG9: 53599485 | CH9: 84700861 | CI9: ='Construction Budget'!Q23*10000000 -> 18681108 | CJ9: 9 | CK9: 7101.0462 | CL9: 11449.86 | CM9: 81305985 | CN9: 97188190 | CO9: ='Construction Budget'!R23*10000000 -> 59156841
A10: On Going | B10: RESIDENTIAL | C10: NYATI EXUBERANCE I | E10: =COUNTIF('Booking Apr'!B:B,'FY Target Sheet'!C10)-COUNTIF('Cancel Apr'!A:A,'FY Target Sheet'!C10) -> 0 | I10: =SUMIF('Booking Apr'!B:B,'FY Target Sheet'!C10,'Booking Apr'!K:K)-SUMIF('Cancel Apr'!A:A,'FY Target Sheet'!C10,'Cancel Apr'!F:F) -> 0 | K10: =SUMIF('Booking Apr'!B:B,C10,'Booking Apr'!L:L)-SUMIF('Cancel Apr'!A:A,'FY Target Sheet'!C10,'Cancel Apr'!G:G) -> 0 | M10: =SUMIF('Coll Apr'!A:A,C10,'Coll Apr'!J:J)*100000 -> 0 | N10: ='Construction Budget'!G26*10000000 -> 0 | O10: ='Construction Budget'!G27*10000000 -> 2635577.4 | Q10: =COUNTIF('Booking May'!B:B,'FY Target Sheet'!C10)-COUNTIF('Cancel May'!A:A,'FY Target Sheet'!C10) -> 0 | U10: =SUMIF('Booking May'!B:B,'FY Target Sheet'!C10,'Booking May'!K:K)-SUMIF('Cancel May'!A:A,'FY Target Sheet'!C10,'Cancel May'!F:F) -> 0 | W10: =SUMIF('Booking May'!B:B,C10,'Booking May'!L:L)-SUMIF('Cancel May'!A:A,'FY Target Sheet'!C10,'Cancel May'!G:G) -> 0 | Y10: =SUMIF('Coll May'!A:A,C10,'Coll May'!J:J)*100000 -> 0 | Z10: ='Construction Budget'!H26*10000000 -> 0 | AA10: ='Construction Budget'!H27*10000000 -> 658894.36 | AC10: =COUNTIF('Booking Jun'!B:B,C10)-COUNTIF('Cancel Jun'!A:A,C10) -> 0 | AG10: =SUMIF('Booking Jun'!B:B,'FY Target Sheet'!C10,'Booking Jun'!K:K)-SUMIF('Cancel Jun'!A:A,'FY Target Sheet'!C10,'Cancel Jun'!F:F) -> 0 | AI10: =SUMIF('Booking Jun'!B:B,C10,'Booking Jun'!L:L)-SUMIF('Cancel Jun'!A:A,'FY Target Sheet'!C10,'Cancel Jun'!G:G) -> 0 | AK10: =SUMIF('Coll Jun'!A:A,C10,'Coll Jun'!J:J)*100000 -> 330000 | AL10: ='Construction Budget'!I26*10000000 -> 0 | AM10: ='Construction Budget'!I27*10000000 -> 732104.76 | AS10: ='Construction Budget'!J26*10000000 -> 0 | AY10: ='Construction Budget'!K26*10000000 -> 2200028.2 | BE10: ='Construction Budget'!L26*10000000 -> 2800035.8 | BK10: ='Construction Budget'!M26*10000000 -> 3200041 | BQ10: ='Construction Budget'!N26*10000000 -> 1800023 | BW10: ='Construction Budget'!O26*10000000 -> 3000038.4 | CC10: ='Construction Budget'!P26*10000000 -> 2600033.3 | CI10: ='Construction Budget'!Q26*10000000 -> 2400030.7 | CO10: ='Construction Budget'!R26*10000000 -> 2000025.6
A11: On Going | B11: RESIDENTIAL | C11: NYATI EXUBERANCE IV | D11: 8 | E11: =COUNTIF('Booking Apr'!B:B,'FY Target Sheet'!C11)-COUNTIF('Cancel Apr'!A:A,'FY Target Sheet'!C11) -> 7 | F11: 5812.5 | G11: =(K11/I11) -> 5790.9594 | H11: 7864 | I11: =SUMIF('Booking Apr'!B:B,'FY Target Sheet'!C11,'Booking Apr'!K:K)-SUMIF('Cancel Apr'!A:A,'FY Target Sheet'!C11,'Cancel Apr'!F:F) -> 6879 | J11: 45709500 | K11: =SUMIF('Booking Apr'!B:B,C11,'Booking Apr'!L:L)-SUMIF('Cancel Apr'!A:A,'FY Target Sheet'!C11,'Cancel Apr'!G:G) -> 39836010 | L11: 45789117 | M11: =SUMIF('Coll Apr'!A:A,C11,'Coll Apr'!J:J)*100000 -> 90754000 | N11: ='Construction Budget'!G29*10000000 -> 10977574 | O11: ='Construction Budget'!G30*10000000 -> 16909781 | P11: 6 | Q11: =COUNTIF('Booking May'!B:B,'FY Target Sheet'!C11)-COUNTIF('Cancel May'!A:A,'FY Target Sheet'!C11) -> 6 | R11: 5900 | S11: =(W11/U11) -> 5759.9613 | T11: 5898 | U11: =SUMIF('Booking May'!B:B,'FY Target Sheet'!C11,'Booking May'!K:K)-SUMIF('Cancel May'!A:A,'FY Target Sheet'!C11,'Cancel May'!F:F) -> 5894 | V11: 34798200 | W11: =SUMIF('Booking May'!B:B,C11,'Booking May'!L:L)-SUMIF('Cancel May'!A:A,'FY Target Sheet'!C11,'Cancel May'!G:G) -> 33949212 | X11: 53412177 | Y11: =SUMIF('Coll May'!A:A,C11,'Coll May'!J:J)*100000 -> 52939000 | Z11: ='Construction Budget'!H29*10000000 -> 11246585 | AA11: ='Construction Budget'!H30*10000000 -> 13814687 | AB11: 5 | AC11: =COUNTIF('Booking Jun'!B:B,C11)-COUNTIF('Cancel Jun'!A:A,C11) -> 12 | AD11: 6000 | AE11: =(AI11/AG11) -> 5774.822 | AF11: 4915 | AG11: =SUMIF('Booking Jun'!B:B,'FY Target Sheet'!C11,'Booking Jun'!K:K)-SUMIF('Cancel Jun'!A:A,'FY Target Sheet'!C11,'Cancel Jun'!F:F) -> 11800 | AH11: 29490000 | AI11: =SUMIF('Booking Jun'!B:B,C11,'Booking Jun'!L:L)-SUMIF('Cancel Jun'!A:A,'FY Target Sheet'!C11,'Cancel Jun'!G:G) -> 68142900 | AJ11: 56017127 | AK11: =SUMIF('Coll Jun'!A:A,C11,'Coll Jun'!J:J)*100000 -> 50007000 | AL11: ='Construction Budget'!I29*10000000 -> 11246585 | AM11: ='Construction Budget'!I30*10000000 -> 24081340 | AN11: 5 | AO11: 5930 | AP11: 4915 | AQ11: 29145950 | AR11: 24016798 | AS11: ='Construction Budget'!J29*10000000 -> 17278220 | AT11: 6 | AU11: 5825 | AV11: 5898 | AW11: 34355850 | AX11: 28344455 | AY11: ='Construction Budget'!K29*10000000 -> 15828617 | AZ11: 7 | BA11: 5878.5714 | BB11: 6881 | BC11: 40450450 | BD11: 32888372 | BE11: ='Construction Budget'!L29*10000000 -> 17487718 | BF11: 0 | BG11: 0 | BH11: 0 | BI11: 0 | BJ11: 50518910 | BK11: ='Construction Budget'!M29*10000000 -> 18681982 | BL11: 0 | BM11: 0 | BN11: 0 | BO11: 0 | BP11: 55605935 | BQ11: ='Construction Budget'!N29*10000000 -> 14820128 | BR11: 0 | BS11: 0 | BT11: 0 | BU11: 0 | BV11: 52779810 | BW11: ='Construction Budget'!O29*10000000 -> 12090612 | BX11: 0 | BY11: 0 | BZ11: 0 | CA11: 0 | CB11: 46235488 | CC11: ='Construction Budget'!P29*10000000 -> 10398135 | CD11: 0 | CE11: 0 | CF11: 0 | CG11: 0 | CH11: 35955765 | CI11: ='Construction Budget'!Q29*10000000 -> 8381156.9 | CJ11: 0 | CK11: 0 | CL11: 0 | CM11: 0 | CN11: 46235488 | CO11: ='Construction Budget'!R29*10000000 -> 1564605.9
A12: On Going | B12: RESIDENTIAL | C12: NYATI ESTEBAN II | D12: 18 | E12: =COUNTIF('Booking Apr'!B:B,'FY Target Sheet'!C12)-COUNTIF('Cancel Apr'!A:A,'FY Target Sheet'!C12) -> 5 | F12: 5916.7872 | G12: =(K12/I12) -> 5986.6978 | H12: 24796 | I12: =SUMIF('Booking Apr'!B:B,'FY Target Sheet'!C12,'Booking Apr'!K:K)-SUMIF('Cancel Apr'!A:A,'FY Target Sheet'!C12,'Cancel Apr'!F:F) -> 8495 | J12: 146712655 | K12: =SUMIF('Booking Apr'!B:B,C12,'Booking Apr'!L:L)-SUMIF('Cancel Apr'!A:A,'FY Target Sheet'!C12,'Cancel Apr'!G:G) -> 50856998 | L12: 51534025 | M12: =SUMIF('Coll Apr'!A:A,C12,'Coll Apr'!J:J)*100000 -> 89573000 | N12: ='Construction Budget'!G32*10000000 -> 52383569 | O12: ='Construction Budget'!G33*10000000 -> 37366645 | P12: 8 | Q12: =COUNTIF('Booking May'!B:B,'FY Target Sheet'!C12)-COUNTIF('Cancel May'!A:A,'FY Target Sheet'!C12) -> 10 | R12: 5924.7482 | S12: =(W12/U12) -> 5878.7526 | T12: 12014 | U12: =SUMIF('Booking May'!B:B,'FY Target Sheet'!C12,'Booking May'!K:K)-SUMIF('Cancel May'!A:A,'FY Target Sheet'!C12,'Cancel May'!F:F) -> 14355 | V12: 71179925 | W12: =SUMIF('Booking May'!B:B,C12,'Booking May'!L:L)-SUMIF('Cancel May'!A:A,'FY Target Sheet'!C12,'Cancel May'!G:G) -> 84389493 | X12: 64306080 | Y12: =SUMIF('Coll May'!A:A,C12,'Coll May'!J:J)*100000 -> 62561000 | Z12: ='Construction Budget'!H32*10000000 -> 57546945 | AA12: ='Construction Budget'!H33*10000000 -> 34447376 | AB12: 12 | AC12: =COUNTIF('Booking Jun'!B:B,C12)-COUNTIF('Cancel Jun'!A:A,C12) -> 17 | AD12: 5914.7009 | AE12: =(AI12/AG12) -> 5861.4946 | AF12: 16180 | AG12: =SUMIF('Booking Jun'!B:B,'FY Target Sheet'!C12,'Booking Jun'!K:K)-SUMIF('Cancel Jun'!A:A,'FY Target Sheet'!C12,'Cancel Jun'!F:F) -> 25194 | AH12: 95699860 | AI12: =SUMIF('Booking Jun'!B:B,C12,'Booking Jun'!L:L)-SUMIF('Cancel Jun'!A:A,'FY Target Sheet'!C12,'Cancel Jun'!G:G) -> 147674494 | AJ12: 58490496 | AK12: =SUMIF('Coll Jun'!A:A,C12,'Coll Jun'!J:J)*100000 -> 80789000 | AL12: ='Construction Budget'!I32*10000000 -> 97656809 | AM12: ='Construction Budget'!I33*10000000 -> 75317143 | AN12: 12 | AO12: 5991.3004 | AP12: 16180 | AQ12: 96939240 | AR12: 69999877 | AS12: ='Construction Budget'!J32*10000000 -> 76170244 | AT12: 22 | AU12: 5993.8736 | AV12: 31592 | AW12: 189358455 | AX12: 88069614 | AY12: ='Construction Budget'!K32*10000000 -> 87151238 | AZ12: 22 | BA12: 5993.8736 | BB12: 31592 | BC12: 189358455 | BD12: 99669827 | BE12: ='Construction Budget'!L32*10000000 -> 84852124 | BF12: 22 | BG12: 6177.345 | BH12: 31066 | BI12: 191905400 | BJ12: 1.1873302e+08 | BK12: ='Construction Budget'!M32*10000000 -> 1.1714737e+08 | BL12: 12 | BM12: 6179.5787 | BN12: 17232 | BO12: 106486500 | BP12: 1.3009362e+08 | BQ12: ='Construction Budget'!N32*10000000 -> 94856488 | BR12: 14 | BS12: 6176.0343 | BT12: 19578 | BU12: 120914400 | BV12: 1.4655568e+08 | BW12: ='Construction Budget'!O32*10000000 -> 86468350 | BX12: 13 | BY12: 6177.6936 | BZ12: 18405 | CA12: 113700450 | CB12: 1.7267991e+08 | CC12: ='Construction Budget'!P32*10000000 -> 87742761 | CD12: 13 | CE12: 6190.9592 | CF12: 45411 | CG12: 281137650 | CH12: 1.7255023e+08 | CI12: ='Construction Budget'!Q32*10000000 -> 76389841 | CJ12: 12 | CK12: 6175.425 | CL12: 16706 | CM12: 103166650 | CN12: 1.925062e+08 | CO12: ='Construction Budget'!R32*10000000 -> 81647059
A13: New | B13: RESIDENTIAL | C13: NYATI ESTEBAN III | E13: =COUNTIF('Booking Apr'!B:B,'FY Target Sheet'!C13)-COUNTIF('Cancel Apr'!A:A,'FY Target Sheet'!C13) -> 0 | I13: =SUMIF('Booking Apr'!B:B,'FY Target Sheet'!C13,'Booking Apr'!K:K)-SUMIF('Cancel Apr'!A:A,'FY Target Sheet'!C13,'Cancel Apr'!F:F) -> 0 | K13: =SUMIF('Booking Apr'!B:B,C13,'Booking Apr'!L:L)-SUMIF('Cancel Apr'!A:A,'FY Target Sheet'!C13,'Cancel Apr'!G:G) -> 0 | M13: =SUMIF('Coll Apr'!A:A,C13,'Coll Apr'!J:J) -> 0 | N13: ='Construction Budget'!G35*10000000 -> 5046916.2 | O13: ='Construction Budget'!G36*10000000 -> 0 | Q13: =COUNTIF('Booking May'!B:B,'FY Target Sheet'!C13)-COUNTIF('Cancel May'!A:A,'FY Target Sheet'!C13) -> 0 | U13: =SUMIF('Booking May'!B:B,'FY Target Sheet'!C13,'Booking May'!K:K)-SUMIF('Cancel May'!A:A,'FY Target Sheet'!C13,'Cancel May'!F:F) -> 0 | W13: =SUMIF('Booking May'!B:B,C13,'Booking May'!L:L)-SUMIF('Cancel May'!A:A,'FY Target Sheet'!C13,'Cancel May'!G:G) -> 0 | Y13: =SUMIF('Coll May'!A:A,C13,'Coll May'!J:J)*100000 -> 0 | Z13: ='Construction Budget'!H35*10000000 -> 7570374.3 | AA13: ='Construction Budget'!H36*10000000 -> 897000 | AC13: =COUNTIF('Booking Jun'!B:B,C13)-COUNTIF('Cancel Jun'!A:A,C13) -> 0 | AG13: =SUMIF('Booking Jun'!B:B,'FY Target Sheet'!C13,'Booking Jun'!K:K)-SUMIF('Cancel Jun'!A:A,'FY Target Sheet'!C13,'Cancel Jun'!F:F) -> 0 | AI13: =SUMIF('Booking Jun'!B:B,C13,'Booking Jun'!L:L)-SUMIF('Cancel Jun'!A:A,'FY Target Sheet'!C13,'Cancel Jun'!G:G) -> 0 | AK13: =SUMIF('Coll Jun'!A:A,C13,'Coll Jun'!J:J)*100000 -> 0 | AL13: ='Construction Budget'!I35*10000000 -> 7570374.3 | AM13: ='Construction Budget'!I36*10000000 -> 0 | AS13: ='Construction Budget'!J35*10000000 -> 8691911.2 | AY13: ='Construction Budget'!K35*10000000 -> 10912554 | BE13: ='Construction Budget'!L35*10000000 -> 12022876 | BK13: ='Construction Budget'!M35*10000000 -> 12022876 | BQ13: ='Construction Budget'!N35*10000000 -> 7177836.4 | BW13: ='Construction Budget'!O35*10000000 -> 6370329.8 | CC13: ='Construction Budget'!P35*10000000 -> 7290887.3 | CI13: ='Construction Budget'!Q35*10000000 -> 15422479 | CO13: ='Construction Budget'!R35*10000000 -> 19902122
A14: Completed | B14: COMMERCIAL | C14: NYATI PLAZA & NYATI ENTHRAL I | D14: 1 | E14: =COUNTIF('Booking Apr'!B:B,'FY Target Sheet'!C14)-COUNTIF('Cancel Apr'!A:A,'FY Target Sheet'!C14) -> 0 | F14: 8000 | H14: 14310 | I14: =SUMIF('Booking Apr'!B:B,'FY Target Sheet'!C14,'Booking Apr'!K:K)-SUMIF('Cancel Apr'!A:A,'FY Target Sheet'!C14,'Cancel Apr'!F:F) -> 0 | J14: 114480000 | K14: =SUMIF('Booking Apr'!B:B,C14,'Booking Apr'!L:L)-SUMIF('Cancel Apr'!A:A,'FY Target Sheet'!C14,'Cancel Apr'!G:G) -> 0 | L14: 1.7697941e+08 | M14: =SUMIF('Coll Apr'!A:A,C14,'Coll Apr'!J:J) -> 0 | P14: 1 | Q14: =COUNTIF('Booking May'!B:B,'FY Target Sheet'!C14)-COUNTIF('Cancel May'!A:A,'FY Target Sheet'!C14) -> 0 | R14: 8000 | T14: 10675 | U14: =SUMIF('Booking May'!B:B,'FY Target Sheet'!C14,'Booking May'!K:K)-SUMIF('Cancel May'!A:A,'FY Target Sheet'!C14,'Cancel May'!F:F) -> 0 | V14: 85400000 | W14: =SUMIF('Booking May'!B:B,C14,'Booking May'!L:L)-SUMIF('Cancel May'!A:A,'FY Target Sheet'!C14,'Cancel May'!G:G) -> 0 | X14: 2.1967941e+08 | Y14: =SUMIF('Coll May'!A:A,C14,'Coll May'!J:J)*100000 -> 0 | AB14: 2 | AC14: =COUNTIF('Booking Jun'!B:B,C14)-COUNTIF('Cancel Jun'!A:A,C14) -> 0 | AD14: 8388.695 | AF14: 17762 | AG14: =SUMIF('Booking Jun'!B:B,'FY Target Sheet'!C14,'Booking Jun'!K:K)-SUMIF('Cancel Jun'!A:A,'FY Target Sheet'!C14,'Cancel Jun'!F:F) -> 0 | AH14: 149000000 | AI14: =SUMIF('Booking Jun'!B:B,C14,'Booking Jun'!L:L)-SUMIF('Cancel Jun'!A:A,'FY Target Sheet'!C14,'Cancel Jun'!G:G) -> 0 | AJ14: 2.3003541e+08 | AK14: =SUMIF('Coll Jun'!A:A,C14,'Coll Jun'!J:J)*100000 -> 0 | AN14: 3 | AO14: 9288.0597 | AP14: 10720 | AQ14: 99568000 | AR14: 2.2503741e+08 | AT14: 3 | AU14: 8889.0033 | AV14: 15532 | AW14: 138064000 | AX14: 2.2647341e+08 | AZ14: 3 | BA14: 6389.3312 | BB14: 14697 | BC14: 93904000 | BD14: 2.3572341e+08 | BF14: 3 | BG14: 8650.8909 | BH14: 21214 | BI14: 183520000 | BJ14: 2.5845141e+08 | BL14: 3 | BM14: 8889.0033 | BN14: 15532 | BO14: 138064000 | BP14: 2.573177e+08 | BR14: 2 | BS14: 10000 | BT14: 6904 | BU14: 69040000 | BV14: 2.000777e+08 | BX14: 2 | BY14: 10000 | BZ14: 6904 | CA14: 69040000 | CB14: 1.655657e+08 | CD14: 2 | CE14: 10000 | CF14: 6904 | CG14: 69040000 | CH14: 82848000 | CJ14: 1 | CK14: 10000 | CL14: 3452 | CM14: 34520000 | CN14: 75944000
A15: Completed | B15: COMMERCIAL | C15: NYATI EMPRESS | D15: 0 | E15: =COUNTIF('Booking Apr'!B:B,'FY Target Sheet'!C15)-COUNTIF('Cancel Apr'!A:A,'FY Target Sheet'!C15) -> 1 | F15: 0 | G15: =(K15/I15) -> 16250 | H15: 0 | I15: =SUMIF('Booking Apr'!B:B,'FY Target Sheet'!C15,'Booking Apr'!K:K)-SUMIF('Cancel Apr'!A:A,'FY Target Sheet'!C15,'Cancel Apr'!F:F) -> 400 | J15: 0 | K15: =SUMIF('Booking Apr'!B:B,C15,'Booking Apr'!L:L)-SUMIF('Cancel Apr'!A:A,'FY Target Sheet'!C15,'Cancel Apr'!G:G) -> 6500000 | L15: 22380250 | M15: =SUMIF('Coll Apr'!A:A,C15,'Coll Apr'!J:J)*100000 -> 650000 | P15: 0 | Q15: =COUNTIF('Booking May'!B:B,'FY Target Sheet'!C15)-COUNTIF('Cancel May'!A:A,'FY Target Sheet'!C15) -> 2 | R15: 0 | S15: =(W15/U15) -> 8394.5774 | T15: 0 | U15: =SUMIF('Booking May'!B:B,'FY Target Sheet'!C15,'Booking May'!K:K)-SUMIF('Cancel May'!A:A,'FY Target Sheet'!C15,'Cancel May'!F:F) -> 3135 | V15: 0 | W15: =SUMIF('Booking May'!B:B,C15,'Booking May'!L:L)-SUMIF('Cancel May'!A:A,'FY Target Sheet'!C15,'Cancel May'!G:G) -> 26317000 | X15: 22380250 | Y15: =SUMIF('Coll May'!A:A,C15,'Coll May'!J:J)*100000 -> 31878000 | AB15: 0 | AC15: =COUNTIF('Booking Jun'!B:B,C15)-COUNTIF('Cancel Jun'!A:A,C15) -> 0 | AD15: 0 | AF15: 0 | AG15: =SUMIF('Booking Jun'!B:B,'FY Target Sheet'!C15,'Booking Jun'!K:K)-SUMIF('Cancel Jun'!A:A,'FY Target Sheet'!C15,'Cancel Jun'!F:F) -> 0 | AH15: 0 | AI15: =SUMIF('Booking Jun'!B:B,C15,'Booking Jun'!L:L)-SUMIF('Cancel Jun'!A:A,'FY Target Sheet'!C15,'Cancel Jun'!G:G) -> 0 | AJ15: 22380250 | AK15: =SUMIF('Coll Jun'!A:A,C15,'Coll Jun'!J:J)*100000 -> 5095000 | AN15: 2 | AO15: 8000 | AP15: 960 | AQ15: 7680000 | AR15: 26220250 | AT15: 2 | AU15: 8000 | AV15: 1074 | AW15: 8592000 | AX15: 8136000 | AZ15: 1 | BA15: 8000 | BB15: 5872 | BC15: 46976000 | BD15: 27784000 | BF15: 0 | BG15: 0 | BH15: 0 | BI15: 0 | BJ15: 23488000 | BL15: 0 | BM15: 0 | BN15: 0 | BO15: 0 | BP15: 0 | BR15: 0 | BS15: 0 | BT15: 0 | BU15: 0 | BV15: 0 | BX15: 0 | BY15: 0 | BZ15: 0 | CA15: 0 | CB15: 0 | CD15: 0 | CE15: 0 | CF15: 0 | CG15: 0 | CH15: 0 | CJ15: 0 | CK15: 0 | CL15: 0 | CM15: 0 | CN15: 0
A16: On Going | B16: LUXURY | C16: NYATI EVOQUE | D16: 1 | E16: =COUNTIF('Booking Apr'!B:B,'FY Target Sheet'!C16)-COUNTIF('Cancel Apr'!A:A,'FY Target Sheet'!C16) -> 2 | F16: 12000 | G16: =(K16/I16) -> 12763.811 | H16: 2150 | I16: =SUMIF('Booking Apr'!B:B,'FY Target Sheet'!C16,'Booking Apr'!K:K)-SUMIF('Cancel Apr'!A:A,'FY Target Sheet'!C16,'Cancel Apr'!F:F) -> 4301 | J16: 25800000 | K16: =SUMIF('Booking Apr'!B:B,C16,'Booking Apr'!L:L)-SUMIF('Cancel Apr'!A:A,'FY Target Sheet'!C16,'Cancel Apr'!G:G) -> 54897150 | L16: 16119500 | M16: =SUMIF('Coll Apr'!A:A,C16,'Coll Apr'!J:J)*100000 -> 41774000 | N16: ='Construction Budget'!G38*10000000 -> 46718535 | O16: ='Construction Budget'!G39*10000000 -> 11355934 | P16: 2 | Q16: =COUNTIF('Booking May'!B:B,'FY Target Sheet'!C16)-COUNTIF('Cancel May'!A:A,'FY Target Sheet'!C16) -> 4 | R16: 12000 | S16: =(W16/U16) -> 11409.271 | T16: 4681 | U16: =SUMIF('Booking May'!B:B,'FY Target Sheet'!C16,'Booking May'!K:K)-SUMIF('Cancel May'!A:A,'FY Target Sheet'!C16,'Cancel May'!F:F) -> 9364 | V16: 56172000 | W16: =SUMIF('Booking May'!B:B,C16,'Booking May'!L:L)-SUMIF('Cancel May'!A:A,'FY Target Sheet'!C16,'Cancel May'!G:G) -> 106836416 | X16: 45546093 | Y16: =SUMIF('Coll May'!A:A,C16,'Coll May'!J:J)*100000 -> 46209000 | Z16: ='Construction Budget'!H38*10000000 -> 49195027 | AA16: ='Construction Budget'!H39*10000000 -> 21503789 | AB16: 2 | AC16: =COUNTIF('Booking Jun'!B:B,C16)-COUNTIF('Cancel Jun'!A:A,C16) -> 3 | AD16: 12000 | AE16: =(AI16/AG16) -> 11034.844 | AF16: 4681 | AG16: =SUMIF('Booking Jun'!B:B,'FY Target Sheet'!C16,'Booking Jun'!K:K)-SUMIF('Cancel Jun'!A:A,'FY Target Sheet'!C16,'Cancel Jun'!F:F) -> 7634 | AH16: 56172000 | AI16: =SUMIF('Booking Jun'!B:B,C16,'Booking Jun'!L:L)-SUMIF('Cancel Jun'!A:A,'FY Target Sheet'!C16,'Cancel Jun'!G:G) -> 84240000 | AJ16: 41582187 | AK16: =SUMIF('Coll Jun'!A:A,C16,'Coll Jun'!J:J)*100000 -> 41837000 | AL16: ='Construction Budget'!I38*10000000 -> 50016851 | AM16: ='Construction Budget'!I39*10000000 -> 44214897 | AN16: 2 | AO16: 12000 | AP16: 4681 | AQ16: 56172000 | AR16: 45150087 | AS16: ='Construction Budget'!J38*10000000 -> 64614159 | AT16: 2 | AU16: 12000 | AV16: 4681 | AW16: 56172000 | AX16: 59362987 | AY16: ='Construction Budget'!K38*10000000 -> 73484312 | AZ16: 3 | BA16: 12000 | BB16: 7212 | BC16: 86544000 | BD16: 66498787 | BE16: ='Construction Budget'!L38*10000000 -> 76996625 | BF16: 3 | BG16: 12000 | BH16: 7212 | BI16: 86544000 | BJ16: 72344587 | BK16: ='Construction Budget'!M38*10000000 -> 71740277 | BL16: 3 | BM16: 12000 | BN16: 7212 | BO16: 86544000 | BP16: 80998987 | BQ16: ='Construction Budget'!N38*10000000 -> 78257760 | BR16: 4 | BS16: 12000 | BT16: 9362 | BU16: 112344000 | BV16: 91702687 | BW16: ='Construction Budget'!O38*10000000 -> 83542749 | BX16: 3 | BY16: 12000 | BZ16: 7212 | CA16: 86544000 | CB16: 1.0159149e+08 | CC16: ='Construction Budget'!P38*10000000 -> 88409218 | CD16: 3 | CE16: 12000 | CF16: 7212 | CG16: 86544000 | CH16: 1.1100519e+08 | CI16: ='Construction Budget'!Q38*10000000 -> 75810732 | CJ16: 2 | CK16: 12000 | CL16: 4681 | CM16: 56172000 | CN16: 1.2603609e+08 | CO16: ='Construction Budget'!R38*10000000 -> 91224634
A17: On Going | B17: LUXURY | C17: NYATI EVANIA | D17: 5 | E17: =COUNTIF('Booking Apr'!B:B,'FY Target Sheet'!C17)-COUNTIF('Cancel Apr'!A:A,'FY Target Sheet'!C17) -> -1 | F17: 10000 | G17: =(K17/I17) -> 10218.352 | H17: 10110.8 | I17: =SUMIF('Booking Apr'!B:B,'FY Target Sheet'!C17,'Booking Apr'!K:K)-SUMIF('Cancel Apr'!A:A,'FY Target Sheet'!C17,'Cancel Apr'!F:F) -> -2661 | J17: 1.01108e+08 | K17: =SUMIF('Booking Apr'!B:B,C17,'Booking Apr'!L:L)-SUMIF('Cancel Apr'!A:A,'FY Target Sheet'!C17,'Cancel Apr'!G:G) -> -27191036 | L17: 20873340 | M17: =SUMIF('Coll Apr'!A:A,C17,'Coll Apr'!J:J)*100000 -> 17494000 | N17: ='Construction Budget'!G41*10000000 -> 50000640 | O17: ='Construction Budget'!G42*10000000 -> 20000000 | P17: 7 | Q17: =COUNTIF('Booking May'!B:B,'FY Target Sheet'!C17)-COUNTIF('Cancel May'!A:A,'FY Target Sheet'!C17) -> 0 | R17: 9793.1135 | T17: 15032.4 | U17: =SUMIF('Booking May'!B:B,'FY Target Sheet'!C17,'Booking May'!K:K)-SUMIF('Cancel May'!A:A,'FY Target Sheet'!C17,'Cancel May'!F:F) -> 0 | V17: 147214000 | W17: =SUMIF('Booking May'!B:B,C17,'Booking May'!L:L)-SUMIF('Cancel May'!A:A,'FY Target Sheet'!C17,'Cancel May'!G:G) -> 0 | X17: 48270388 | Y17: =SUMIF('Coll May'!A:A,C17,'Coll May'!J:J)*100000 -> 13921000 | Z17: ='Construction Budget'!H41*10000000 -> 45000576 | AA17: ='Construction Budget'!H42*10000000 -> 11800000 | AB17: 6 | AC17: =COUNTIF('Booking Jun'!B:B,C17)-COUNTIF('Cancel Jun'!A:A,C17) -> 3 | AD17: 9772.7538 | AE17: =(AI17/AG17) -> 10238.918 | AF17: 13685.6 | AG17: =SUMIF('Booking Jun'!B:B,'FY Target Sheet'!C17,'Booking Jun'!K:K)-SUMIF('Cancel Jun'!A:A,'FY Target Sheet'!C17,'Cancel Jun'!F:F) -> 5690 | AH17: 133746000 | AI17: =SUMIF('Booking Jun'!B:B,C17,'Booking Jun'!L:L)-SUMIF('Cancel Jun'!A:A,'FY Target Sheet'!C17,'Cancel Jun'!G:G) -> 58259443 | AJ17: 59175805 | AK17: =SUMIF('Coll Jun'!A:A,C17,'Coll Jun'!J:J)*100000 -> 4259000 | AL17: ='Construction Budget'!I41*10000000 -> 42500544 | AM17: ='Construction Budget'!I42*10000000 -> 25100000 | AN17: 6 | AO17: 10500 | AP17: 12650.4 | AQ17: 1.328292e+08 | AR17: 65817265 | AS17: ='Construction Budget'!J41*10000000 -> 67500864 | AT17: 6 | AU17: 10500 | AV17: 12650.4 | AW17: 1.328292e+08 | AX17: 72458725 | AY17: ='Construction Budget'!K41*10000000 -> 75000960 | AZ17: 7 | BA17: 10293.114 | BB17: 15032.4 | BC17: 154730200 | BD17: 83515965 | BE17: ='Construction Budget'!L41*10000000 -> 97501248 | BF17: 7 | BG17: 12868.927 | BH17: 19249.6 | BI17: 247721700 | BJ17: 1.1050893e+08 | BK17: ='Construction Budget'!M41*10000000 -> 102501312 | BL17: 7 | BM17: 10602.002 | BN17: 15760.4 | BO17: 167091800 | BP17: 1.3743963e+08 | BQ17: ='Construction Budget'!N41*10000000 -> 92501184 | BR17: 7 | BS17: 10594.835 | BT17: 15032.4 | BU17: 159265800 | BV17: 1.4027636e+08 | BW17: ='Construction Budget'!O41*10000000 -> 107501376 | BX17: 8 | BY17: 12883.992 | BZ17: 21324.4 | CA17: 274743400 | CB17: 1.8275119e+08 | CC17: ='Construction Budget'!P41*10000000 -> 1.0000128e+08 | CD17: 6 | CE17: 10892.116 | CF17: 14413.6 | CG17: 156994600 | CH17: 1.9878981e+08 | CI17: ='Construction Budget'!Q41*10000000 -> 1.2000154e+08 | CJ17: 8 | CK17: 12883.992 | CL17: 21324.4 | CM17: 274743400 | CN17: 3.1322509e+08 | CO17: ='Construction Budget'!R41*10000000 -> 1.0000128e+08
A18: On Going | B18: LUXURY | C18: NYATI ELENOR | D18: 4 | E18: =COUNTIF('Booking Apr'!B:B,'FY Target Sheet'!C18)-COUNTIF('Cancel Apr'!A:A,'FY Target Sheet'!C18) -> 6 | F18: 10500 | G18: =(K18/I18) -> 10289.492 | H18: 10809 | I18: =SUMIF('Booking Apr'!B:B,'FY Target Sheet'!C18,'Booking Apr'!K:K)-SUMIF('Cancel Apr'!A:A,'FY Target Sheet'!C18,'Cancel Apr'!F:F) -> 20670 | J18: 113494500 | K18: =SUMIF('Booking Apr'!B:B,C18,'Booking Apr'!L:L)-SUMIF('Cancel Apr'!A:A,'FY Target Sheet'!C18,'Cancel Apr'!G:G) -> 212683800 | L18: 42298642 | M18: =SUMIF('Coll Apr'!A:A,C18,'Coll Apr'!J:J)*100000 -> 49550000 | N18: ='Construction Budget'!G44*10000000 -> 26595671 | O18: ='Construction Budget'!G45*10000000 -> 12800000 | P18: 4 | Q18: =COUNTIF('Booking May'!B:B,'FY Target Sheet'!C18)-COUNTIF('Cancel May'!A:A,'FY Target Sheet'!C18) -> 11 | R18: 10500 | S18: =(W18/U18) -> 10838.323 | T18: 11546 | U18: =SUMIF('Booking May'!B:B,'FY Target Sheet'!C18,'Booking May'!K:K)-SUMIF('Cancel May'!A:A,'FY Target Sheet'!C18,'Cancel May'!F:F) -> 32735 | V18: 121233000 | W18: =SUMIF('Booking May'!B:B,C18,'Booking May'!L:L)-SUMIF('Cancel May'!A:A,'FY Target Sheet'!C18,'Cancel May'!G:G) -> 354792500 | X18: 63296167 | Y18: =SUMIF('Coll May'!A:A,C18,'Coll May'!J:J)*100000 -> 99094000 | Z18: ='Construction Budget'!H44*10000000 -> 31755809 | AA18: ='Construction Budget'!H45*10000000 -> 13300000 | AB18: 2 | AC18: =COUNTIF('Booking Jun'!B:B,C18)-COUNTIF('Cancel Jun'!A:A,C18) -> 6 | AD18: 10500 | AE18: =(AI18/AG18) -> 10791.803 | AF18: 5036 | AG18: =SUMIF('Booking Jun'!B:B,'FY Target Sheet'!C18,'Booking Jun'!K:K)-SUMIF('Cancel Jun'!A:A,'FY Target Sheet'!C18,'Cancel Jun'!F:F) -> 18677 | AH18: 52878000 | AI18: =SUMIF('Booking Jun'!B:B,C18,'Booking Jun'!L:L)-SUMIF('Cancel Jun'!A:A,'FY Target Sheet'!C18,'Cancel Jun'!G:G) -> 201558500 | AJ18: 85940067 | AK18: =SUMIF('Coll Jun'!A:A,C18,'Coll Jun'!J:J)*100000 -> 191033000 | AL18: ='Construction Budget'!I44*10000000 -> 34033665 | AM18: ='Construction Budget'!I45*10000000 -> 17300000 | AN18: 3 | AO18: 11000 | AP18: 9633 | AQ18: 105963000 | AR18: 1.0123822e+08 | AS18: ='Construction Budget'!J44*10000000 -> 39354441 | AT18: 3 | AU18: 11000 | AV18: 8291 | AW18: 91201000 | AX18: 1.129609e+08 | AY18: ='Construction Budget'!K44*10000000 -> 44958707 | AZ18: 3 | BA18: 11000 | BB18: 9028 | BC18: 99308000 | BD18: 1.179263e+08 | BE18: ='Construction Budget'!L44*10000000 -> 46022074 | BF18: 3 | BG18: 11250 | BH18: 8291 | BI18: 93273750 | BJ18: 1.2204187e+08 | BK18: ='Construction Budget'!M44*10000000 -> 51939085 | BL18: 5 | BM18: 11250 | BN18: 15406 | BO18: 173317500 | BP18: 1.2822504e+08 | BQ18: ='Construction Budget'!N44*10000000 -> 55018808 | BR18: 4 | BS18: 11250 | BT18: 12888 | BU18: 144990000 | BV18: 1.4874189e+08 | BW18: ='Construction Budget'!O44*10000000 -> 56187625 | BX18: 4 | BY18: 11500 | BZ18: 11546 | CA18: 132779000 | CB18: 1.964979e+08 | CC18: ='Construction Budget'!P44*10000000 -> 65595318 | CD18: 4 | CE18: 11500 | CF18: 11546 | CG18: 132779000 | CH18: 2.2308483e+08 | CI18: ='Construction Budget'!Q44*10000000 -> 71260038 | CJ18: 3 | CK18: 11500 | CL18: 8291 | CM18: 95346500 | CN18: 2.3925843e+08 | CO18: ='Construction Budget'!R44*10000000 -> 77286441
A19: On Going | B19: LUXURY | C19: NYATI EMBLEM | D19: 1 | E19: =COUNTIF('Booking Apr'!B:B,'FY Target Sheet'!C19)-COUNTIF('Cancel Apr'!A:A,'FY Target Sheet'!C19) -> 1 | F19: 10200 | G19: =(K19/I19) -> 12548.051 | H19: 3642 | I19: =SUMIF('Booking Apr'!B:B,'FY Target Sheet'!C19,'Booking Apr'!K:K)-SUMIF('Cancel Apr'!A:A,'FY Target Sheet'!C19,'Cancel Apr'!F:F) -> 3642 | J19: 37148400 | K19: =SUMIF('Booking Apr'!B:B,C19,'Booking Apr'!L:L)-SUMIF('Cancel Apr'!A:A,'FY Target Sheet'!C19,'Cancel Apr'!G:G) -> 45700000 | L19: 19832853 | M19: =SUMIF('Coll Apr'!A:A,C19,'Coll Apr'!J:J)*100000 -> 16135000 | N19: ='Construction Budget'!G47*10000000 -> 38517160 | O19: ='Construction Budget'!G48*10000000 -> 13259925 | P19: 1 | Q19: =COUNTIF('Booking May'!B:B,'FY Target Sheet'!C19)-COUNTIF('Cancel May'!A:A,'FY Target Sheet'!C19) -> 1 | R19: 10200 | S19: =(W19/U19) -> 10021.966 | T19: 3642 | U19: =SUMIF('Booking May'!B:B,'FY Target Sheet'!C19,'Booking May'!K:K)-SUMIF('Cancel May'!A:A,'FY Target Sheet'!C19,'Cancel May'!F:F) -> 3642 | V19: 37148400 | W19: =SUMIF('Booking May'!B:B,C19,'Booking May'!L:L)-SUMIF('Cancel May'!A:A,'FY Target Sheet'!C19,'Cancel May'!G:G) -> 36500000 | X19: 19832853 | Y19: =SUMIF('Coll May'!A:A,C19,'Coll May'!J:J)*100000 -> 10773000 | Z19: ='Construction Budget'!H47*10000000 -> 29214945 | AA19: ='Construction Budget'!H48*10000000 -> 13454924 | AB19: 1 | AC19: =COUNTIF('Booking Jun'!B:B,C19)-COUNTIF('Cancel Jun'!A:A,C19) -> 1 | AD19: 10200 | AE19: =(AI19/AG19) -> 10708.402 | AF19: 3642 | AG19: =SUMIF('Booking Jun'!B:B,'FY Target Sheet'!C19,'Booking Jun'!K:K)-SUMIF('Cancel Jun'!A:A,'FY Target Sheet'!C19,'Cancel Jun'!F:F) -> 3642 | AH19: 37148400 | AI19: =SUMIF('Booking Jun'!B:B,C19,'Booking Jun'!L:L)-SUMIF('Cancel Jun'!A:A,'FY Target Sheet'!C19,'Cancel Jun'!G:G) -> 39000000 | AJ19: 23547693 | AK19: =SUMIF('Coll Jun'!A:A,C19,'Coll Jun'!J:J)*100000 -> 4123000 | AL19: ='Construction Budget'!I47*10000000 -> 28839922 | AM19: ='Construction Budget'!I48*10000000 -> 16379908 | AN19: 2 | AO19: 10200 | AP19: 7284 | AQ19: 74296800 | AR19: 27262533 | AS19: ='Construction Budget'!J47*10000000 -> 35083818 | AT19: 2 | AU19: 10200 | AV19: 7284 | AW19: 74296800 | AX19: 30977373 | AY19: ='Construction Budget'!K47*10000000 -> 53628330 | AZ19: 2 | BA19: 10200 | BB19: 7284 | BC19: 74296800 | BD19: 36549633 | BE19: ='Construction Budget'!L47*10000000 -> 51087723 | BF19: 2 | BG19: 10200 | BH19: 7284 | BI19: 74296800 | BJ19: 43979313 | BK19: ='Construction Budget'!M47*10000000 -> 67418686 | BL19: 2 | BM19: 10200 | BN19: 7284 | BO19: 74296800 | BP19: 49551573 | BQ19: ='Construction Budget'!N47*10000000 -> 50254097 | BR19: 2 | BS19: 10200 | BT19: 7284 | BU19: 74296800 | BV19: 62553513 | BW19: ='Construction Budget'!O47*10000000 -> 51453710 | BX19: 3 | BY19: 10200 | BZ19: 10926 | CA19: 111445200 | CB19: 73698033 | CC19: ='Construction Budget'!P47*10000000 -> 58015379 | CD19: 3 | CE19: 10200 | CF19: 10926 | CG19: 111445200 | CH19: 88557393 | CI19: ='Construction Budget'!Q47*10000000 -> 58003366 | CJ19: 3 | CK19: 10200 | CL19: 10926 | CM19: 111445200 | CN19: 1.0341675e+08 | CO19: ='Construction Budget'!R47*10000000 -> 78490543
A20: Completed | B20: COMMERCIAL | C20: NYATI ELAN COMMERCIAL | E20: =COUNTIF('Booking Apr'!B:B,'FY Target Sheet'!C20)-COUNTIF('Cancel Apr'!A:A,'FY Target Sheet'!C20) -> 0 | L20: 2252000 | M20: =SUMIF('Coll Apr'!A:A,C20,'Coll Apr'!J:J)*100000 -> 7627000 | Q20: =COUNTIF('Booking May'!B:B,'FY Target Sheet'!C20)-COUNTIF('Cancel May'!A:A,'FY Target Sheet'!C20) -> 0 | U20: =SUMIF('Booking May'!B:B,'FY Target Sheet'!C20,'Booking May'!K:K)-SUMIF('Cancel May'!A:A,'FY Target Sheet'!C20,'Cancel May'!F:F) -> 0 | W20: =SUMIF('Booking May'!B:B,C20,'Booking May'!L:L)-SUMIF('Cancel May'!A:A,'FY Target Sheet'!C20,'Cancel May'!G:G) -> 0 | X20: 3788333.3 | Y20: =SUMIF('Coll May'!A:A,C20,'Coll May'!J:J)*100000 -> 0 | AC20: =COUNTIF('Booking Jun'!B:B,C20)-COUNTIF('Cancel Jun'!A:A,C20) -> 0 | AG20: =SUMIF('Booking Jun'!B:B,'FY Target Sheet'!C20,'Booking Jun'!K:K)-SUMIF('Cancel Jun'!A:A,'FY Target Sheet'!C20,'Cancel Jun'!F:F) -> 0 | AI20: =SUMIF('Booking Jun'!B:B,C20,'Booking Jun'!L:L)-SUMIF('Cancel Jun'!A:A,'FY Target Sheet'!C20,'Cancel Jun'!G:G) -> 0 | AJ20: 3788333.3 | AK20: =SUMIF('Coll Jun'!A:A,C20,'Coll Jun'!J:J)*100000 -> 777000 | AR20: 3788333.3 | AX20: 3788333.3 | BD20: 3788333.3 | BJ20: 1536333.3 | BP20: 0 | BV20: 0 | CB20: 0 | CH20: 0 | CN20: 0
A21: Completed | B21: RESIDENTIAL | C21: NYATI DEFENCE ENCLAVE III | E21: =COUNTIF('Booking Apr'!B:B,'FY Target Sheet'!C21)-COUNTIF('Cancel Apr'!A:A,'FY Target Sheet'!C21) -> 0 | L21: 840000 | M21: =SUMIF('Coll Apr'!A:A,C21,'Coll Apr'!J:J)*100000 -> 3578000 | Q21: =COUNTIF('Booking May'!B:B,'FY Target Sheet'!C21)-COUNTIF('Cancel May'!A:A,'FY Target Sheet'!C21) -> 1 | U21: =SUMIF('Booking May'!B:B,'FY Target Sheet'!C21,'Booking May'!K:K)-SUMIF('Cancel May'!A:A,'FY Target Sheet'!C21,'Cancel May'!F:F) -> 581 | W21: =SUMIF('Booking May'!B:B,C21,'Booking May'!L:L)-SUMIF('Cancel May'!A:A,'FY Target Sheet'!C21,'Cancel May'!G:G) -> 1627000 | X21: 2738000 | Y21: =SUMIF('Coll May'!A:A,C21,'Coll May'!J:J)*100000 -> 161000 | AC21: =COUNTIF('Booking Jun'!B:B,C21)-COUNTIF('Cancel Jun'!A:A,C21) -> 0 | AG21: =SUMIF('Booking Jun'!B:B,'FY Target Sheet'!C21,'Booking Jun'!K:K)-SUMIF('Cancel Jun'!A:A,'FY Target Sheet'!C21,'Cancel Jun'!F:F) -> 0 | AI21: =SUMIF('Booking Jun'!B:B,C21,'Booking Jun'!L:L)-SUMIF('Cancel Jun'!A:A,'FY Target Sheet'!C21,'Cancel Jun'!G:G) -> 0 | AJ21: 0 | AK21: =SUMIF('Coll Jun'!A:A,C21,'Coll Jun'!J:J)*100000 -> 0 | AR21: 0 | AX21: 0 | BD21: 0 | BJ21: 0 | BP21: 0 | BV21: 0 | CB21: 0 | CH21: 0 | CN21: 0
A22: On Going | B22: COMMERCIAL | C22: NYATI QUANTUM TOWERS | E22: =COUNTIF('Booking Apr'!B:B,'FY Target Sheet'!C22)-COUNTIF('Cancel Apr'!A:A,'FY Target Sheet'!C22) -> 0 | M22: =SUMIF('Coll Apr'!A:A,C22,'Coll Apr'!J:J) -> 0 | N22: ='Construction Budget'!G53*10000000 -> 33000422 | O22: ='Construction Budget'!G54*10000000 -> 26800000 | Q22: =COUNTIF('Booking May'!B:B,'FY Target Sheet'!C22)-COUNTIF('Cancel May'!A:A,'FY Target Sheet'!C22) -> 0 | U22: =SUMIF('Booking May'!B:B,'FY Target Sheet'!C22,'Booking May'!K:K)-SUMIF('Cancel May'!A:A,'FY Target Sheet'!C22,'Cancel May'!F:F) -> 0 | W22: =SUMIF('Booking May'!B:B,C22,'Booking May'!L:L)-SUMIF('Cancel May'!A:A,'FY Target Sheet'!C22,'Cancel May'!G:G) -> 0 | Y22: =SUMIF('Coll May'!A:A,C22,'Coll May'!J:J)*100000 -> 0 | Z22: ='Construction Budget'!H53*10000000 -> 39000499 | AA22: ='Construction Budget'!H54*10000000 -> 15713000 | AC22: =COUNTIF('Booking Jun'!B:B,C22)-COUNTIF('Cancel Jun'!A:A,C22) -> 0 | AG22: =SUMIF('Booking Jun'!B:B,'FY Target Sheet'!C22,'Booking Jun'!K:K)-SUMIF('Cancel Jun'!A:A,'FY Target Sheet'!C22,'Cancel Jun'!F:F) -> 0 | AI22: =SUMIF('Booking Jun'!B:B,C22,'Booking Jun'!L:L)-SUMIF('Cancel Jun'!A:A,'FY Target Sheet'!C22,'Cancel Jun'!G:G) -> 0 | AK22: =SUMIF('Coll Jun'!A:A,C22,'Coll Jun'!J:J)*100000 -> 0 | AL22: ='Construction Budget'!I53*10000000 -> 36000461 | AM22: ='Construction Budget'!I54*10000000 -> 31500000 | AS22: ='Construction Budget'!J53*10000000 -> 51000653 | AY22: ='Construction Budget'!K53*10000000 -> 46500595 | BE22: ='Construction Budget'!L53*10000000 -> 49500634 | BK22: ='Construction Budget'!M53*10000000 -> 54000691 | BQ22: ='Construction Budget'!N53*10000000 -> 57000730 | BW22: ='Construction Budget'!O53*10000000 -> 51000653 | CC22: ='Construction Budget'!P53*10000000 -> 55500710 | CI22: ='Construction Budget'!Q53*10000000 -> 63000806 | CO22: ='Construction Budget'!R53*10000000 -> 64500826
A23: On Going | B23: COMMERCIAL | C23: NYATI UNITREE EXTENSION | E23: =COUNTIF('Booking Apr'!B:B,'FY Target Sheet'!C23)-COUNTIF('Cancel Apr'!A:A,'FY Target Sheet'!C23) -> 0 | M23: =SUMIF('Coll Apr'!A:A,C23,'Coll Apr'!J:J) -> 0 | N23: ='Construction Budget'!G56*10000000 -> 11000141 | O23: ='Construction Budget'!G57*10000000 -> 7900000 | Q23: =COUNTIF('Booking May'!B:B,'FY Target Sheet'!C23)-COUNTIF('Cancel May'!A:A,'FY Target Sheet'!C23) -> 0 | U23: =SUMIF('Booking May'!B:B,'FY Target Sheet'!C23,'Booking May'!K:K)-SUMIF('Cancel May'!A:A,'FY Target Sheet'!C23,'Cancel May'!F:F) -> 0 | W23: =SUMIF('Booking May'!B:B,C23,'Booking May'!L:L)-SUMIF('Cancel May'!A:A,'FY Target Sheet'!C23,'Cancel May'!G:G) -> 0 | Y23: =SUMIF('Coll May'!A:A,C23,'Coll May'!J:J)*100000 -> 0 | Z23: ='Construction Budget'!H56*10000000 -> 12500160 | AA23: ='Construction Budget'!H57*10000000 -> 9800000 | AC23: =COUNTIF('Booking Jun'!B:B,C23)-COUNTIF('Cancel Jun'!A:A,C23) -> 0 | AG23: =SUMIF('Booking Jun'!B:B,'FY Target Sheet'!C23,'Booking Jun'!K:K)-SUMIF('Cancel Jun'!A:A,'FY Target Sheet'!C23,'Cancel Jun'!F:F) -> 0 | AI23: =SUMIF('Booking Jun'!B:B,C23,'Booking Jun'!L:L)-SUMIF('Cancel Jun'!A:A,'FY Target Sheet'!C23,'Cancel Jun'!G:G) -> 0 | AK23: =SUMIF('Coll Jun'!A:A,C23,'Coll Jun'!J:J)*100000 -> 0 | AL23: ='Construction Budget'!I56*10000000 -> 11500147 | AM23: ='Construction Budget'!I57*10000000 -> 13000000 | AS23: ='Construction Budget'!J56*10000000 -> 17000218 | AY23: ='Construction Budget'!K56*10000000 -> 18000230 | BE23: ='Construction Budget'!L56*10000000 -> 20500262 | BK23: ='Construction Budget'!M56*10000000 -> 18000230 | BQ23: ='Construction Budget'!N56*10000000 -> 19000243 | BW23: ='Construction Budget'!O56*10000000 -> 18500237 | CC23: ='Construction Budget'!P56*10000000 -> 18000230 | CI23: ='Construction Budget'!Q56*10000000 -> 22000282 | CO23: ='Construction Budget'!R56*10000000 -> 14000179
